<?xml version="1.0"?>
<robot xmlns:xacro="http://www.ros.org/wiki/xacro">
  <xacro:macro name="link1" params="parent">

    <link name="body1">
      <visual>
        <origin xyz="0 0 0.02" rpy="0 0 0" />
        <geometry>
          <box size="0.02 0.02 0.05"/> 
        </geometry>
        <material name="grey"/>
      </visual>
      <inertial>
        <mass value="0.194"/>
        <origin xyz="0.005 -0.001 0.016"/> 
        <inertia ixx="0.000189" ixy="0.000005" ixz="0.000054" iyy="0.000213" iyz="0.000003" izz="0.000067"/> 
      </inertial>
    </link>

    <joint name="link0_to_body1" type="fixed">
      <origin xyz="0 0 0" rpy="0 0 0"/> 
      <parent link="${parent}"/>
      <child link="body1"/>
    </joint>

    <link name="link1">
      <visual>
        <geometry>
          <cylinder radius="0.015" length="0.04"/> 
        </geometry>
      </visual>
    </link>

    <joint name="joint2" type="revolute">
      <axis xyz="0 0 1"/> 
      <dynamics damping="1.0" friction="1.0"/> 
      <limit effort="100" lower="-3.1416" upper="3.1416" velocity="0.5"/>
      <origin xyz="-0.02 0 0.0462" rpy="1.5707 0 3.1415"/> 
      <parent link="${parent}"/>
      <child link="link1"/>
    </joint>

    <transmission name="joint2_transmission">
      <type>transmission_interface/SimpleTransmission</type>
      <joint name="joint2">
        <hardwareInterface>hardware_interface/PositionJointInterface</hardwareInterface>
      </joint>
    </transmission>

  </xacro:macro>
</robot>