<?xml version="1.0" ?>
<!-- =================================================================================== -->
<!-- |    This document was autogenerated by xacro from xacro/main.xacro               | -->
<!-- |    EDITING THIS FILE BY HAND IS NOT RECOMMENDED                                 | -->
<!-- =================================================================================== -->
<robot name="robot_arm">
  <link name="base_link"/>
  <link name="link0">
    <visual>
      <geometry>
        <cylinder length="0.04" radius="0.015"/>
      </geometry>
      <origin rpy="0 0 0" xyz="0 0 0"/>
    </visual>
  </link>
  <joint name="joint1" type="revolute">
    <axis xyz="0 0 1"/>
    <limit effort="1" lower="-3.1416" upper="3.1416" velocity="0.5"/>
    <origin rpy="0 0 0" xyz="0 0 0"/>
    <parent link="base_link"/>
    <child link="link0"/>
  </joint>
  <link name="link1">
    <visual>
      <geometry>
        <cylinder length="0.04" radius="0.015"/>
      </geometry>
    </visual>
    <collision>
      <geometry>
        <cylinder length="0.04" radius="0.015"/>
      </geometry>
    </collision>
    <inertial>
      <mass value="0.194"/>
      <origin xyz="0 0 0"/>
      <inertia ixx="0.0" ixy="0.0" ixz="0.0" iyy="0.0" iyz="0.0" izz="0.0"/>
    </inertial>
  </link>
  <joint name="joint2" type="revolute">
    <axis xyz="0 0 1"/>
    <limit effort="1" lower="-3.1416" upper="3.1416" velocity="0.5"/>
    <origin rpy="1.5707 0 3.1415" xyz="-0.02 0 0.0462"/>
    <parent link="link0"/>
    <child link="link1"/>
  </joint>
  <link name="link2">
    <visual>
      <geometry>
        <cylinder length="0.04" radius="0.015"/>
      </geometry>
    </visual>
    <collision>
      <geometry>
        <cylinder length="0.04" radius="0.015"/>
      </geometry>
    </collision>
    <inertial>
      <mass value="0.194"/>
      <origin xyz="0 0 0"/>
      <inertia ixx="0.0" ixy="0.0" ixz="0.0" iyy="0.0" iyz="0.0" izz="0.0"/>
    </inertial>
  </link>
  <joint name="joint3" type="revolute">
    <axis xyz="0 0 1"/>
    <limit effort="1" lower="-3.1416" upper="3.1416" velocity="0.5"/>
    <origin rpy="3.1415 0 0" xyz="0.15071 0 0"/>
    <parent link="link1"/>
    <child link="link2"/>
  </joint>
  <link name="link3">
    <visual>
      <geometry>
        <cylinder length="0.04" radius="0.015"/>
      </geometry>
    </visual>
    <collision>
      <geometry>
        <cylinder length="0.04" radius="0.015"/>
      </geometry>
    </collision>
    <inertial>
      <mass value="0.194"/>
      <origin xyz="0 0 0"/>
      <inertia ixx="0.0" ixy="0.0" ixz="0.0" iyy="0.0" iyz="0.0" izz="0.0"/>
    </inertial>
  </link>
  <joint name="joint4" type="revolute">
    <axis xyz="0 0 1"/>
    <limit effort="1" lower="-3.1416" upper="3.1416" velocity="0.5"/>
    <origin rpy=" -1.5707 0 -1.3021" xyz="0.00531 -0.01928 0"/>
    <parent link="link2"/>
    <child link="link3"/>
  </joint>
  <link name="link4">
    <visual>
      <geometry>
        <box size="0.01 0.01 0.01"/>
      </geometry>
    </visual>
    <collision>
      <geometry>
        <box size="0.01 0.01 0.01"/>
      </geometry>
    </collision>
    <inertial>
      <mass value="0.194"/>
      <origin xyz="0 0 0"/>
      <inertia ixx="0.0" ixy="0.0" ixz="0.0" iyy="0.0" iyz="0.0" izz="0.0"/>
    </inertial>
  </link>
  <joint name="link3_to_link4" type="fixed">
    <origin rpy=" 1.5707 0 1.5707" xyz="0 0 -0.18"/>
    <parent link="link3"/>
    <child link="link4"/>
  </joint>
  <link name="link5">
    <visual>
      <geometry>
        <box size="0.01 0.01 0.01"/>
      </geometry>
    </visual>
    <collision>
      <geometry>
        <box size="0.01 0.01 0.01"/>
      </geometry>
    </collision>
    <inertial>
      <mass value="0.194"/>
      <origin xyz="0 0 0"/>
      <inertia ixx="0.0" ixy="0.0" ixz="0.0" iyy="0.0" iyz="0.0" izz="0.0"/>
    </inertial>
  </link>
  <joint name="link4_to_link5" type="fixed">
    <origin rpy="0 0 -1.5707" xyz="0 0 0"/>
    <parent link="link4"/>
    <child link="link5"/>
  </joint>
</robot>
