<?xml version="1.0" ?>
<!-- =================================================================================== -->
<!-- |    This document was autogenerated by xacro from xacro/main.xacro               | -->
<!-- |    EDITING THIS FILE BY HAND IS NOT RECOMMENDED                                 | -->
<!-- =================================================================================== -->
<robot name="robot_arm">
  <link name="base_link"/>
  <material name="grey">
    <color rgba="0.4 0.4 0.4 1"/>
  </material>
  <!-- <xacro:include filename="plugins.xacro"/> -->
  <link name="body0">
    <visual>
      <origin rpy="0 0 0" xyz="-0.075 0 0"/>
      <geometry>
        <box size="0.15 0.02 0.02"/>
      </geometry>
      <material name="grey"/>
    </visual>
    <inertial>
      <mass value="0.341"/>
      <origin xyz="-0.075 -0.006 -0.003"/>
      <inertia ixx="0.000099" ixy="0.000139" ixz="0.000115" iyy="0.002920" iyz="0.000003" izz="0.002934"/>
    </inertial>
  </link>
  <joint name="base_link_to_body0" type="fixed">
    <origin rpy="0 0 0" xyz="0 0 0"/>
    <parent link="base_link"/>
    <child link="body0"/>
  </joint>
  <link name="link0">
    <visual>
      <geometry>
        <cylinder length="0.04" radius="0.015"/>
      </geometry>
    </visual>
  </link>
  <joint name="joint1" type="revolute">
    <axis xyz="0 0 1"/>
    <dynamics damping="1.0" friction="1.0"/>
    <limit effort="100" lower="-3.1416" upper="3.1416" velocity="0.5"/>
    <origin rpy="0 0 0" xyz="0 0 0"/>
    <parent link="base_link"/>
    <child link="link0"/>
  </joint>
  <transmission name="joint1_transmission">
    <type>transmission_interface/SimpleTransmission</type>
    <joint name="joint1">
      <hardwareInterface>hardware_interface/PositionJointInterface</hardwareInterface>
    </joint>
  </transmission>
  <link name="body1">
    <visual>
      <origin rpy="0 0 0" xyz="0 0 0.02"/>
      <geometry>
        <box size="0.02 0.02 0.05"/>
      </geometry>
      <material name="grey"/>
    </visual>
    <inertial>
      <mass value="0.194"/>
      <origin xyz="0.005 -0.001 0.016"/>
      <inertia ixx="0.000189" ixy="0.000005" ixz="0.000054" iyy="0.000213" iyz="0.000003" izz="0.000067"/>
    </inertial>
  </link>
  <joint name="link0_to_body1" type="fixed">
    <origin rpy="0 0 0" xyz="0 0 0"/>
    <parent link="link0"/>
    <child link="body1"/>
  </joint>
  <link name="link1">
    <visual>
      <geometry>
        <cylinder length="0.04" radius="0.015"/>
      </geometry>
    </visual>
  </link>
  <joint name="joint2" type="revolute">
    <axis xyz="0 0 1"/>
    <dynamics damping="1.0" friction="1.0"/>
    <limit effort="100" lower="-3.1416" upper="3.1416" velocity="0.5"/>
    <origin rpy="1.5707 0 3.1415" xyz="-0.02 0 0.0462"/>
    <parent link="link0"/>
    <child link="link1"/>
  </joint>
  <transmission name="joint2_transmission">
    <type>transmission_interface/SimpleTransmission</type>
    <joint name="joint2">
      <hardwareInterface>hardware_interface/PositionJointInterface</hardwareInterface>
    </joint>
  </transmission>
  <link name="body2">
    <visual>
      <origin rpy="0 0 0" xyz="0.075 0 0"/>
      <geometry>
        <box size="0.15 0.02 0.02"/>
      </geometry>
      <material name="grey"/>
    </visual>
    <inertial>
      <mass value="0.429"/>
      <origin xyz="0.073 0 0"/>
      <inertia ixx="0.000087" ixy="-0.000076" ixz="-0.000010" iyy="0.003190" iyz="0" izz="0.003213"/>
    </inertial>
  </link>
  <joint name="link1_to_body2" type="fixed">
    <origin rpy="0 0 0" xyz="0 0 0"/>
    <parent link="link1"/>
    <child link="body2"/>
  </joint>
  <link name="link2">
    <visual>
      <geometry>
        <cylinder length="0.04" radius="0.015"/>
      </geometry>
    </visual>
  </link>
  <joint name="joint3" type="revolute">
    <axis xyz="0 0 1"/>
    <dynamics damping="1.0" friction="1.0"/>
    <limit effort="100" lower="-3.1416" upper="3.1416" velocity="0.5"/>
    <origin rpy="3.1415 0 0" xyz="0.15071 0 0"/>
    <parent link="link1"/>
    <child link="link2"/>
  </joint>
  <transmission name="joint3_transmission">
    <type>transmission_interface/SimpleTransmission</type>
    <joint name="joint3">
      <hardwareInterface>hardware_interface/PositionJointInterface</hardwareInterface>
    </joint>
  </transmission>
  <link name="body3">
    <visual>
      <origin rpy="0 0 0" xyz="0 -0.02 0"/>
      <geometry>
        <box size="0.02 0.02 0.02"/>
      </geometry>
      <material name="grey"/>
    </visual>
    <inertial>
      <mass value="0.115"/>
      <origin xyz="0.017 -0.026 -0.002"/>
      <inertia ixx="0.000120" ixy="-0.000061" ixz="-0.000001" iyy="0.000062" iyz="0" izz="0.000156"/>
    </inertial>
  </link>
  <joint name="link2_to_body3" type="fixed">
    <origin rpy="0 0 0" xyz="0 0 0"/>
    <parent link="link2"/>
    <child link="body3"/>
  </joint>
  <link name="link3">
    <visual>
      <geometry>
        <cylinder length="0.04" radius="0.015"/>
      </geometry>
    </visual>
  </link>
  <joint name="joint4" type="revolute">
    <axis xyz="0 0 1"/>
    <dynamics damping="1.0" friction="1.0"/>
    <limit effort="100" lower="-3.1416" upper="3.1416" velocity="0.5"/>
    <origin rpy=" -1.5707 0 -1.3021" xyz="0.00531 -0.01928 0"/>
    <parent link="link2"/>
    <child link="link3"/>
  </joint>
  <transmission name="joint4_transmission">
    <type>transmission_interface/SimpleTransmission</type>
    <joint name="joint4">
      <hardwareInterface>hardware_interface/PositionJointInterface</hardwareInterface>
    </joint>
  </transmission>
  <link name="body4">
    <visual>
      <origin rpy="0 0 0" xyz="0 0 -0.08"/>
      <geometry>
        <box size="0.02 0.02 0.16"/>
      </geometry>
      <material name="grey"/>
    </visual>
    <inertial>
      <mass value="0.333"/>
      <origin xyz="0 0.003 -0.098"/>
      <inertia ixx="0.003709" ixy="0.000002" ixz="-0.000004" iyy="0.003734" iyz="0" izz="0.000079"/>
    </inertial>
  </link>
  <joint name="link3_to_body4" type="fixed">
    <origin rpy="0 0 0" xyz="0 0 0"/>
    <parent link="link3"/>
    <child link="body4"/>
  </joint>
  <link name="link4">
    <visual>
      <geometry>
        <box size="0.01 0.01 0.01"/>
      </geometry>
    </visual>
  </link>
  <joint name="link3_to_link4" type="fixed">
    <origin rpy=" 1.5707 0 1.5707" xyz="0 0 -0.18"/>
    <parent link="link3"/>
    <child link="link4"/>
  </joint>
  <link name="link5">
    <visual>
      <geometry>
        <box size="0.01 0.01 0.01"/>
      </geometry>
    </visual>
  </link>
  <joint name="link4_to_link5" type="fixed">
    <origin rpy="0 0 -1.5707" xyz="0 0 0"/>
    <parent link="link4"/>
    <child link="link5"/>
  </joint>
</robot>
